[2025-01-14T03:35:09.374+0000] {local_task_job_runner.py:123} INFO - ::group::Pre task execution logs
[2025-01-14T03:35:09.394+0000] {taskinstance.py:2613} INFO - Dependencies all met for dep_context=non-requeueable deps ti=<TaskInstance: train_and_update_model.check_and_train manual__2025-01-14T03:33:05.283708+00:00 [queued]>
[2025-01-14T03:35:09.405+0000] {taskinstance.py:2613} INFO - Dependencies all met for dep_context=requeueable deps ti=<TaskInstance: train_and_update_model.check_and_train manual__2025-01-14T03:33:05.283708+00:00 [queued]>
[2025-01-14T03:35:09.406+0000] {taskinstance.py:2866} INFO - Starting attempt 2 of 3
[2025-01-14T03:35:09.422+0000] {taskinstance.py:2889} INFO - Executing <Task(PythonOperator): check_and_train> on 2025-01-14 03:33:05.283708+00:00
[2025-01-14T03:35:09.431+0000] {warnings.py:112} WARNING - /home/***/.local/lib/python3.12/site-packages/***/task/task_runner/standard_task_runner.py:70: DeprecationWarning: This process (pid=213) is multi-threaded, use of fork() may lead to deadlocks in the child.
  pid = os.fork()

[2025-01-14T03:35:09.433+0000] {standard_task_runner.py:72} INFO - Started process 215 to run task
[2025-01-14T03:35:09.433+0000] {standard_task_runner.py:104} INFO - Running: ['***', 'tasks', 'run', 'train_and_update_model', 'check_and_train', 'manual__2025-01-14T03:33:05.283708+00:00', '--job-id', '33', '--raw', '--subdir', 'DAGS_FOLDER/craw_check_update.py', '--cfg-path', '/tmp/tmpufzrsf12']
[2025-01-14T03:35:09.435+0000] {standard_task_runner.py:105} INFO - Job 33: Subtask check_and_train
[2025-01-14T03:35:09.486+0000] {task_command.py:467} INFO - Running <TaskInstance: train_and_update_model.check_and_train manual__2025-01-14T03:33:05.283708+00:00 [running]> on host 0d9f7ac256fb
[2025-01-14T03:35:09.575+0000] {taskinstance.py:3132} INFO - Exporting env vars: AIRFLOW_CTX_DAG_OWNER='***' AIRFLOW_CTX_DAG_ID='train_and_update_model' AIRFLOW_CTX_TASK_ID='check_and_train' AIRFLOW_CTX_EXECUTION_DATE='2025-01-14T03:33:05.283708+00:00' AIRFLOW_CTX_TRY_NUMBER='2' AIRFLOW_CTX_DAG_RUN_ID='manual__2025-01-14T03:33:05.283708+00:00'
[2025-01-14T03:35:09.577+0000] {logging_mixin.py:190} INFO - Task instance is in running state
[2025-01-14T03:35:09.577+0000] {logging_mixin.py:190} INFO -  Previous state of the Task instance: queued
[2025-01-14T03:35:09.578+0000] {logging_mixin.py:190} INFO - Current task name:check_and_train state:running start_date:2025-01-14 03:35:09.395139+00:00
[2025-01-14T03:35:09.579+0000] {logging_mixin.py:190} INFO - Dag name:train_and_update_model and current dag run status:running
[2025-01-14T03:35:09.579+0000] {taskinstance.py:731} INFO - ::endgroup::
[2025-01-14T03:35:09.581+0000] {craw_check_update.py:39} INFO - === Bắt đầu quá trình kiểm tra model ===
[2025-01-14T03:35:09.583+0000] {craw_check_update.py:45} INFO - Ngày hiện tại: 2025_01_14, Ngày trước đó: 2025_01_13
[2025-01-14T03:35:09.584+0000] {taskinstance.py:3311} ERROR - Task failed with exception
Traceback (most recent call last):
  File "/home/airflow/.local/lib/python3.12/site-packages/airflow/models/taskinstance.py", line 767, in _execute_task
    result = _execute_callable(context=context, **execute_callable_kwargs)
             ^^^^^^^^^^^^^^^^^^^^^^^^^^^^^^^^^^^^^^^^^^^^^^^^^^^^^^^^^^^^^
  File "/home/airflow/.local/lib/python3.12/site-packages/airflow/models/taskinstance.py", line 733, in _execute_callable
    return ExecutionCallableRunner(
           ^^^^^^^^^^^^^^^^^^^^^^^^
  File "/home/airflow/.local/lib/python3.12/site-packages/airflow/utils/operator_helpers.py", line 252, in run
    return self.func(*args, **kwargs)
           ^^^^^^^^^^^^^^^^^^^^^^^^^^
  File "/home/airflow/.local/lib/python3.12/site-packages/airflow/models/baseoperator.py", line 417, in wrapper
    return func(self, *args, **kwargs)
           ^^^^^^^^^^^^^^^^^^^^^^^^^^^
  File "/home/airflow/.local/lib/python3.12/site-packages/airflow/operators/python.py", line 238, in execute
    return_value = self.execute_callable()
                   ^^^^^^^^^^^^^^^^^^^^^^^
  File "/home/airflow/.local/lib/python3.12/site-packages/airflow/operators/python.py", line 256, in execute_callable
    return runner.run(*self.op_args, **self.op_kwargs)
           ^^^^^^^^^^^^^^^^^^^^^^^^^^^^^^^^^^^^^^^^^^^
  File "/home/airflow/.local/lib/python3.12/site-packages/airflow/utils/operator_helpers.py", line 252, in run
    return self.func(*args, **kwargs)
           ^^^^^^^^^^^^^^^^^^^^^^^^^^
  File "/opt/airflow/dags/craw_check_update.py", line 136, in check_and_train
    eval_model(current_day)
  File "/opt/airflow/dags/craw_check_update.py", line 47, in eval_model
    current_result_path = os.path.join(EXPERIMENT_DIR, f'{CURRENT_DAY}', 'results.csv')
                                       ^^^^^^^^^^^^^^
NameError: name 'EXPERIMENT_DIR' is not defined
[2025-01-14T03:35:09.604+0000] {logging_mixin.py:190} INFO - Task instance in failure state
[2025-01-14T03:35:09.605+0000] {logging_mixin.py:190} INFO - Task start:2025-01-14 03:35:09.395139+00:00 end:2025-01-14 03:35:09.604050+00:00 duration:0.208911
[2025-01-14T03:35:09.606+0000] {logging_mixin.py:190} INFO - Task:<Task(PythonOperator): check_and_train> dag:<DAG: train_and_update_model> dagrun:<DagRun train_and_update_model @ 2025-01-14 03:33:05.283708+00:00: manual__2025-01-14T03:33:05.283708+00:00, state:running, queued_at: 2025-01-14 03:33:05.310730+00:00. externally triggered: True>
[2025-01-14T03:35:09.607+0000] {logging_mixin.py:190} INFO - Failure caused by name 'EXPERIMENT_DIR' is not defined
[2025-01-14T03:35:09.607+0000] {taskinstance.py:1225} INFO - Marking task as UP_FOR_RETRY. dag_id=train_and_update_model, task_id=check_and_train, run_id=manual__2025-01-14T03:33:05.283708+00:00, execution_date=20250114T033305, start_date=20250114T033509, end_date=20250114T033509
[2025-01-14T03:35:09.624+0000] {taskinstance.py:340} INFO - ::group::Post task execution logs
[2025-01-14T03:35:09.625+0000] {standard_task_runner.py:124} ERROR - Failed to execute job 33 for task check_and_train (name 'EXPERIMENT_DIR' is not defined; 215)
Traceback (most recent call last):
  File "/home/airflow/.local/lib/python3.12/site-packages/airflow/task/task_runner/standard_task_runner.py", line 117, in _start_by_fork
    ret = args.func(args, dag=self.dag)
          ^^^^^^^^^^^^^^^^^^^^^^^^^^^^^
  File "/home/airflow/.local/lib/python3.12/site-packages/airflow/cli/cli_config.py", line 49, in command
    return func(*args, **kwargs)
           ^^^^^^^^^^^^^^^^^^^^^
  File "/home/airflow/.local/lib/python3.12/site-packages/airflow/utils/cli.py", line 116, in wrapper
    return f(*args, **kwargs)
           ^^^^^^^^^^^^^^^^^^
  File "/home/airflow/.local/lib/python3.12/site-packages/airflow/cli/commands/task_command.py", line 483, in task_run
    task_return_code = _run_task_by_selected_method(args, _dag, ti)
                       ^^^^^^^^^^^^^^^^^^^^^^^^^^^^^^^^^^^^^^^^^^^^
  File "/home/airflow/.local/lib/python3.12/site-packages/airflow/cli/commands/task_command.py", line 256, in _run_task_by_selected_method
    return _run_raw_task(args, ti)
           ^^^^^^^^^^^^^^^^^^^^^^^
  File "/home/airflow/.local/lib/python3.12/site-packages/airflow/cli/commands/task_command.py", line 341, in _run_raw_task
    return ti._run_raw_task(
           ^^^^^^^^^^^^^^^^^
  File "/home/airflow/.local/lib/python3.12/site-packages/airflow/utils/session.py", line 97, in wrapper
    return func(*args, session=session, **kwargs)
           ^^^^^^^^^^^^^^^^^^^^^^^^^^^^^^^^^^^^^^
  File "/home/airflow/.local/lib/python3.12/site-packages/airflow/models/taskinstance.py", line 3005, in _run_raw_task
    return _run_raw_task(
           ^^^^^^^^^^^^^^
  File "/home/airflow/.local/lib/python3.12/site-packages/airflow/models/taskinstance.py", line 273, in _run_raw_task
    TaskInstance._execute_task_with_callbacks(
  File "/home/airflow/.local/lib/python3.12/site-packages/airflow/models/taskinstance.py", line 3159, in _execute_task_with_callbacks
    result = self._execute_task(context, task_orig)
             ^^^^^^^^^^^^^^^^^^^^^^^^^^^^^^^^^^^^^^
  File "/home/airflow/.local/lib/python3.12/site-packages/airflow/models/taskinstance.py", line 3183, in _execute_task
    return _execute_task(self, context, task_orig)
           ^^^^^^^^^^^^^^^^^^^^^^^^^^^^^^^^^^^^^^^
  File "/home/airflow/.local/lib/python3.12/site-packages/airflow/models/taskinstance.py", line 767, in _execute_task
    result = _execute_callable(context=context, **execute_callable_kwargs)
             ^^^^^^^^^^^^^^^^^^^^^^^^^^^^^^^^^^^^^^^^^^^^^^^^^^^^^^^^^^^^^
  File "/home/airflow/.local/lib/python3.12/site-packages/airflow/models/taskinstance.py", line 733, in _execute_callable
    return ExecutionCallableRunner(
           ^^^^^^^^^^^^^^^^^^^^^^^^
  File "/home/airflow/.local/lib/python3.12/site-packages/airflow/utils/operator_helpers.py", line 252, in run
    return self.func(*args, **kwargs)
           ^^^^^^^^^^^^^^^^^^^^^^^^^^
  File "/home/airflow/.local/lib/python3.12/site-packages/airflow/models/baseoperator.py", line 417, in wrapper
    return func(self, *args, **kwargs)
           ^^^^^^^^^^^^^^^^^^^^^^^^^^^
  File "/home/airflow/.local/lib/python3.12/site-packages/airflow/operators/python.py", line 238, in execute
    return_value = self.execute_callable()
                   ^^^^^^^^^^^^^^^^^^^^^^^
  File "/home/airflow/.local/lib/python3.12/site-packages/airflow/operators/python.py", line 256, in execute_callable
    return runner.run(*self.op_args, **self.op_kwargs)
           ^^^^^^^^^^^^^^^^^^^^^^^^^^^^^^^^^^^^^^^^^^^
  File "/home/airflow/.local/lib/python3.12/site-packages/airflow/utils/operator_helpers.py", line 252, in run
    return self.func(*args, **kwargs)
           ^^^^^^^^^^^^^^^^^^^^^^^^^^
  File "/opt/airflow/dags/craw_check_update.py", line 136, in check_and_train
    eval_model(current_day)
  File "/opt/airflow/dags/craw_check_update.py", line 47, in eval_model
    current_result_path = os.path.join(EXPERIMENT_DIR, f'{CURRENT_DAY}', 'results.csv')
                                       ^^^^^^^^^^^^^^
NameError: name 'EXPERIMENT_DIR' is not defined
[2025-01-14T03:35:09.655+0000] {local_task_job_runner.py:266} INFO - Task exited with return code 1
[2025-01-14T03:35:09.677+0000] {taskinstance.py:3895} INFO - 0 downstream tasks scheduled from follow-on schedule check
[2025-01-14T03:35:09.680+0000] {local_task_job_runner.py:245} INFO - ::endgroup::
